Workbook

Sheet README
A1: Mumbai Population Database
A2: Compiled from public Census of India data and published demographic estimates
A4: IMPORTANT CONTEXT
A5: • India's last full Census was in 2011. The 2021 Census was postponed (COVID-19) and has not yet been conducted as of 2026.
A6: • All figures for 2001 and 2011 in this workbook are ACTUAL CENSUS DATA (blue font).
A7: • All figures for 2012 onward are ESTIMATES / PROJECTIONS (black font, formula-driven from a growth rate), not headcounts, unless a specific published estimate is cited.
A8: • "Mumbai" is reported under several different geographic boundaries — figures differ a lot depending on which one a source uses:
A9: 1. Mumbai City district (Island City) — 157 km²
A10: 2. Mumbai Suburban district — 446 km²
A11: 3. Greater Mumbai (Mumbai City + Mumbai Suburban, i.e. the Municipal Corporation area, "MCGM") — 603 km²
A12: 4. Mumbai Urban Agglomeration (UA) — Greater Mumbai + contiguous urban outgrowths — ~20.7M in 2011
A13: 5. Mumbai Metropolitan Region (MMR) — Greater Mumbai + Thane, Navi Mumbai, Kalyan, Vasai-Virar, etc. — 6,328 km²
... A37: Black text = calculated by formula (projection / derived value)

Sheet Population_by_Year
A1: Mumbai — Year-wise Population by Geography (2001–2031)
A3: GROWTH RATE ASSUMPTIONS (derived from actual anchor-year data; used to project forward)
A4: Geography | B4: Anchor Year 1 | C4: Anchor Pop 1 | D4: Anchor Year 2 | E4: Anchor Pop 2 | F4: CAGR (annual growth rate, formula)
A5: Mumbai City district | B5: 2001 | C5: 3338297 | D5: 2011 | E5: 3085411 | F5: =(E5/C5)^(1/(D5-B5))-1 -> -0.0078466454
A6: Mumbai Suburban district | B6: 2001 | C6: 8640358 | D6: 2011 | E6: 9356962 | F6: =(E6/C6)^(1/(D6-B6))-1 -> 0.0079994911
A7: Greater Mumbai (City+Suburban, MCGM) | B7: 2001 | C7: 11978450 | D7: 2011 | E7: 12442373 | F7: =(E7/C7)^(1/(D7-B7))-1 -> 0.0038070909
A8: Mumbai Urban Agglomeration (UA) | B8: 2001 | C8: 16434386 | D8: 2011 | E8: 20748395 | F8: =(E8/C8)^(1/(D8-B8))-1 -> 0.02358309
A9: Mumbai Metropolitan Region (MMR) | B9: 2011 | C9: 22800000 | D9: 2023 | E9: 27230000 | F9: =(E9/C9)^(1/(D9-B9))-1 -> 0.014906575
A11: Note: 2001 figures for City/Suburban districts are back-calculated from published 2001 density figures (density × area). UA and MMR anchors are as published by cited sources (see README); different sources define these boundaries slightly differently.
A13: YEAR-WISE POPULATION TABLE
A14: Year | B14: Mumbai City district | C14: Mumbai Suburban district | D14: Greater Mumbai (MCGM) | E14: Mumbai Urban Agglomeration | F14: Mumbai Metro Region (MMR) | G14: Data Type | H14: Notes
A15: 2001 | B15: 3338297 | C15: 8640358 | D15: 11978450 | E15: 16434386 | F15: n/a | G15: Actual (Census) | H15: Census year
A16: 2002 | B16: =B15*(1+$F$5) -> 3312102.6 | C16: =C15*(1+$F$6) -> 8709476.5 | D16: =B16+C16 -> 12021579 | E16: =E15*(1+$F$8) -> 16821960 | F16: n/a | G16: Projected
A17: 2003 | B17: =B16*(1+$F$5) -> 3286113.7 | C17: =C16*(1+$F$6) -> 8779147.8 | D17: =B17+C17 -> 12065262 | E17: =E16*(1+$F$8) -> 17218673 | F17: n/a | G17: Projected
A18: 2004 | B18: =B17*(1+$F$5) -> 3260328.7 | C18: =C17*(1+$F$6) -> 8849376.6 | D18: =B18+C18 -> 12109705 | E18: =E17*(1+$F$8) -> 17624743 | F18: n/a | G18: Projected
A19: 2005 | B19: =B18*(1+$F$5) -> 3234746.1 | C19: =C18*(1+$F$6) -> 8920167.1 | D19: =B19+C19 -> 12154913 | E19: =E18*(1+$F$8) -> 18040389 | F19: n/a | G19: Projected
A20: 2006 | B20: =B19*(1+$F$5) -> 3209364.2 | C20: =C19*(1+$F$6) -> 8991523.9 | D20: =B20+C20 -> 12200888 | E20: =E19*(1+$F$8) -> 18465837 | F20: n/a | G20: Projected
A21: 2007 | B21: =B20*(1+$F$5) -> 3184181.4 | C21: =C20*(1+$F$6) -> 9063451.5 | D21: =B21+C21 -> 12247633 | E21: =E20*(1+$F$8) -> 18901318 | F21: n/a | G21: Projected
A22: 2008 | B22: =B21*(1+$F$5) -> 3159196.3 | C22: =C21*(1+$F$6) -> 9135954.5 | D22: =B22+C22 -> 12295151 | E22: =E21*(1+$F$8) -> 19347070 | F22: n/a | G22: Projected
A23: 2009 | B23: =B22*(1+$F$5) -> 3134407.2 | C23: =C22*(1+$F$6) -> 9209037.5 | D23: =B23+C23 -> 12343445 | E23: =E22*(1+$F$8) -> 19803334 | F23: n/a | G23: Projected
A24: 2010 | B24: =B23*(1+$F$5) -> 3109812.6 | C24: =C23*(1+$F$6) -> 9282705.1 | D24: =B24+C24 -> 12392518 | E24: =E23*(1+$F$8) -> 20270357 | F24: n/a | G24: Projected
A25: 2011 | B25: 3085411 | C25: 9356962 | D25: 12442373 | E25: 20748395 | F25: 22800000 | G25: Actual (Census) | H25: Census year
A26: 2012 | B26: =B25*(1+$F$5) -> 3061200.9 | C26: =C25*(1+$F$6) -> 9431812.9 | D26: =B26+C26 -> 12493014 | E26: =E25*(1+$F$8) -> 21237706 | F26: =F25*(1+$F$9) -> 23139870 | G26: Projected
A27: 2013 | B27: =B26*(1+$F$5) -> 3037180.7 | C27: =C26*(1+$F$6) -> 9507262.6 | D27: =B27+C27 -> 12544443 | E27: =E26*(1+$F$8) -> 21738557 | F27: =F26*(1+$F$9) -> 23484806 | G27: Projected
A28: 2014 | B28: =B27*(1+$F$5) -> 3013349 | C28: =C27*(1+$F$6) -> 9583315.9 | D28: =B28+C28 -> 12596665 | E28: =E27*(1+$F$8) -> 22251219 | F28: =F27*(1+$F$9) -> 23834884 | G28: Projected
A29: 2015 | B29: =B28*(1+$F$5) -> 2989704.4 | C29: =C28*(1+$F$6) -> 9659977.6 | D29: =B29+C29 -> 12649682 | E29: =E28*(1+$F$8) -> 22775972 | F29: =F28*(1+$F$9) -> 24190181 | G29: Projected
A30: 2016 | B30: =B29*(1+$F$5) -> 2966245.2 | C30: =C29*(1+$F$6) -> 9737252.5 | D30: =B30+C30 -> 12703498 | E30: =E29*(1+$F$8) -> 23313100 | F30: =F29*(1+$F$9) -> 24550773 | G30: Projected
A31: 2017 | B31: =B30*(1+$F$5) -> 2942970.1 | C31: =C30*(1+$F$6) -> 9815145.5 | D31: =B31+C31 -> 12758116 | E31: =E30*(1+$F$8) -> 23862895 | F31: =F30*(1+$F$9) -> 24916741 | G31: Projected
A32: 2018 | B32: =B31*(1+$F$5) -> 2919877.7 | C32: =C31*(1+$F$6) -> 9893661.7 | D32: =B32+C32 -> 12813539 | E32: =E31*(1+$F$8) -> 24425655 | F32: =F31*(1+$F$9) -> 25288165 | G32: Projected
A33: 2019 | B33: =B32*(1+$F$5) -> 2896966.4 | C33: =C32*(1+$F$6) -> 9972805.9 | D33: =B33+C33 -> 12869772 | E33: =E32*(1+$F$8) -> 25001688 | F33: =F32*(1+$F$9) -> 25665125 | G33: Projected
A34: 2020 | B34: =B33*(1+$F$5) -> 2874235 | C34: =C33*(1+$F$6) -> 10052583 | D34: =B34+C34 -> 12926818 | E34: =E33*(1+$F$8) -> 25591305 | F34: =F33*(1+$F$9) -> 26047704 | G34: Projected
A35: 2021 | B35: =B34*(1+$F$5) -> 2851681.9 | C35: =C34*(1+$F$6) -> 10132999 | D35: =B35+C35 -> 12984681 | E35: =E34*(1+$F$8) -> 26194827 | F35: 27070000 | G35: Published estimate
A36: 2022 | B36: =B35*(1+$F$5) -> 2829305.7 | C36: =C35*(1+$F$6) -> 10214058 | D36: =B36+C36 -> 13043363 | E36: =E35*(1+$F$8) -> 26812582 | F36: 27120000 | G36: Published estimate
A37: 2023 | B37: =B36*(1+$F$5) -> 2807105.2 | C37: =C36*(1+$F$6) -> 10295765 | D37: =B37+C37 -> 13102870 | E37: =E36*(1+$F$8) -> 27444905 | F37: 27230000 | G37: Published estimate
A38: 2024 | B38: =B37*(1+$F$5) -> 2785078.8 | C38: =C37*(1+$F$6) -> 10378126 | D38: =B38+C38 -> 13163205 | E38: =E37*(1+$F$8) -> 28092141 | F38: =F37*(1+$F$9) -> 27635906 | G38: Projected
A39: 2025 | B39: =B38*(1+$F$5) -> 2763225.3 | C39: =C38*(1+$F$6) -> 10461146 | D39: =B39+C39 -> 13224371 | E39: =E38*(1+$F$8) -> 28754640 | F39: =F38*(1+$F$9) -> 28047863 | G39: Projected
A40: 2026 | B40: =B39*(1+$F$5) -> 2741543.2 | C40: =C39*(1+$F$6) -> 10544829 | D40: =B40+C40 -> 13286373 | E40: =E39*(1+$F$8) -> 29432764 | F40: 27800000 | G40: Published estimate
A41: 2027 | B41: =B40*(1+$F$5) -> 2720031.3 | C41: =C40*(1+$F$6) -> 10629183 | D41: =B41+C41 -> 13349214 | E41: =E40*(1+$F$8) -> 30126879 | F41: =F40*(1+$F$9) -> 28214403 | G41: Projected
A42: 2028 | B42: =B41*(1+$F$5) -> 2698688.2 | C42: =C41*(1+$F$6) -> 10714211 | D42: =B42+C42 -> 13412899 | E42: =E41*(1+$F$8) -> 30837364 | F42: =F41*(1+$F$9) -> 28634983 | G42: Projected
A43: 2029 | B43: =B42*(1+$F$5) -> 2677512.6 | C43: =C42*(1+$F$6) -> 10799919 | D43: =B43+C43 -> 13477432 | E43: =E42*(1+$F$8) -> 31564604 | F43: =F42*(1+$F$9) -> 29061832 | G43: Projected
...

Sheet Population_Density
A1: Mumbai — Population Density by District (people per km²)
A3: Region | B3: Area (km²) | C3: Pop 2001 | D3: Density 2001 | E3: Pop 2011 | F3: Density 2011 | G3: Pop 2021 (proj.) | H3: Density 2021 (proj.) | I3: Pop 2026 (proj.) | J3: Density 2026 (proj.)
A4: Mumbai City district | B4: 157 | C4: =Population_by_Year!B15 -> 3338297 | D4: =C4/B4 -> 21263.038 | E4: =Population_by_Year!B25 -> 3085411 | F4: =E4/B4 -> 19652.299 | G4: =Population_by_Year!B35 -> 2851681.9 | H4: =G4/B4 -> 18163.579 | I4: =Population_by_Year!B40 -> 2741543.2 | J4: =I4/B4 -> 17462.059
A5: Mumbai Suburban district | B5: 446 | C5: =Population_by_Year!C15 -> 8640358 | D5: =C5/B5 -> 19373 | E5: =Population_by_Year!C25 -> 9356962 | F5: =E5/B5 -> 20979.735 | G5: =Population_by_Year!C35 -> 10132999 | H5: =G5/B5 -> 22719.728 | I5: =Population_by_Year!C40 -> 10544829 | J5: =I5/B5 -> 23643.115
A6: Greater Mumbai (MCGM, total) | B6: 603 | C6: =Population_by_Year!D15 -> 11978450 | D6: =C6/B6 -> 19864.76 | E6: =Population_by_Year!D25 -> 12442373 | F6: =E6/B6 -> 20634.118 | G6: =Population_by_Year!D35 -> 12984681 | H6: =G6/B6 -> 21533.467 | I6: =Population_by_Year!D40 -> 13286373 | J6: =I6/B6 -> 22033.786
A8: MMR (Mumbai Metropolitan Region) | B8: 6328 | C8: n/a | D8: n/a | E8: =Population_by_Year!F25 -> 22800000 | F8: =E8/B8 -> 3603.0341 | G8: =Population_by_Year!F35 -> 27070000 | H8: =G8/B8 -> 4277.8129 | I8: =Population_by_Year!F40 -> 27800000 | J8: =I8/B8 -> 4393.1732
A10: Note: Density = Population ÷ Area. 2021/2026 columns use projected population from the Population_by_Year sheet (growth-rate model), not a re-measured area.

Sheet Age_Groups_2011
A1: Mumbai — Age-Group Breakdown (2011 Census base year)
A3: Mumbai City district — actual Census 2011 figures where available
A4: Age Group | B4: Population | C4: % of District Total | D4: Data Type | E4: Source / Method
A5: 0–6 years (children) | B5: 272886 | C5: =B5/Population_by_Year!B25 -> 0.088443971 | D5: Actual (Census 2011) | E5: census2011.co.in — Mumbai City district child population
A6: 7–14 years | B6: =ROUND(Population_by_Year!B25*0.14,0) -> 431958 | C6: 0.14 | D6: Estimated | E6: Modeled: national 2011 age-structure ratio (~14% of total) applied to district total, since Mumbai-specific split was not found in public sources
A7: 15–59 years (working age) | B7: =ROUND(Population_by_Year!B25*0.63,0) -> 1943809 | C7: 0.63 | D7: Estimated | E7: Modeled: national 2011 age-structure ratio (~63% of total)
A8: 60+ years (elderly) | B8: =ROUND(Population_by_Year!B25*0.086,0) -> 265345 | C8: 0.086 | D8: Estimated | E8: Modeled: Census 2011 national ratio = 8.6% of total population
A9: TOTAL (check) | B9: =SUM(B5:B8) -> 2913998 | C9: =B9/Population_by_Year!B25 -> 0.94444403
A11: Caveat: Only the 0–6 child figure is Mumbai-specific actual Census data. The 7–14 / 15–59 / 60+ splits use INDIA-wide 2011 age-structure ratios applied to Mumbai's population, because granular Mumbai-only age-band tables (Census C-13/C-14 series) were not available through public web search. For precise Mumbai figures, pull table C-13 from censusindia.gov.in or an Indiastat.com subscription.

Sheet Elderly_Population_Trend
A1: Mumbai — Estimated Elderly (60+) Population, Year-wise
A3: Method: applies the national 60+ population share (rising over time per UNDESA projections) to Mumbai's Greater Mumbai (MCGM) population for each year.
A5: Year | B5: Greater Mumbai Population | C5: National 60+ Share (interpolated) | D5: Estimated 60+ Population (Mumbai) | E5: Data Type | F5: Source
A6: 2001 | B6: =Population_by_Year!D15 -> 11978450 | C6: =$C$15+($C$16-$C$15)/(2011-2010)*(2001-2010) -> -0.024 | D6: =B6*C6 -> -287482.8 | E6: Interpolated/Extrapolated | F6: Modeled
A7: 2002 | B7: =Population_by_Year!D16 -> 12021579 | C7: =$C$15+($C$16-$C$15)/(2011-2010)*(2002-2010) -> -0.013 | D7: =B7*C7 -> -156280.53 | E7: Interpolated/Extrapolated | F7: Modeled
A8: 2003 | B8: =Population_by_Year!D17 -> 12065262 | C8: =$C$15+($C$16-$C$15)/(2011-2010)*(2003-2010) -> -0.002 | D8: =B8*C8 -> -24130.523 | E8: Interpolated/Extrapolated | F8: Modeled
A9: 2004 | B9: =Population_by_Year!D18 -> 12109705 | C9: =$C$15+($C$16-$C$15)/(2011-2010)*(2004-2010) -> 0.009 | D9: =B9*C9 -> 108987.35 | E9: Interpolated/Extrapolated | F9: Modeled
A10: 2005 | B10: =Population_by_Year!D19 -> 12154913 | C10: =$C$15+($C$16-$C$15)/(2011-2010)*(2005-2010) -> 0.02 | D10: =B10*C10 -> 243098.26 | E10: Interpolated/Extrapolated | F10: Modeled
A11: 2006 | B11: =Population_by_Year!D20 -> 12200888 | C11: =$C$15+($C$16-$C$15)/(2011-2010)*(2006-2010) -> 0.031 | D11: =B11*C11 -> 378227.53 | E11: Interpolated/Extrapolated | F11: Modeled
A12: 2007 | B12: =Population_by_Year!D21 -> 12247633 | C12: =$C$15+($C$16-$C$15)/(2011-2010)*(2007-2010) -> 0.042 | D12: =B12*C12 -> 514400.58 | E12: Interpolated/Extrapolated | F12: Modeled
A13: 2008 | B13: =Population_by_Year!D22 -> 12295151 | C13: =$C$15+($C$16-$C$15)/(2011-2010)*(2008-2010) -> 0.053 | D13: =B13*C13 -> 651642.99 | E13: Interpolated/Extrapolated | F13: Modeled
A14: 2009 | B14: =Population_by_Year!D23 -> 12343445 | C14: =$C$15+($C$16-$C$15)/(2011-2010)*(2009-2010) -> 0.064 | D14: =B14*C14 -> 789980.46 | E14: Interpolated/Extrapolated | F14: Modeled
A15: 2010 | B15: =Population_by_Year!D24 -> 12392518 | C15: 0.075 | D15: =B15*C15 -> 929438.83 | E15: Published estimate (UNDESA) | F15: UNDESA 2008 projection
A16: 2011 | B16: =Population_by_Year!D25 -> 12442373 | C16: 0.086 | D16: =B16*C16 -> 1070044.1 | E16: Actual (Census) | F16: Census 2011 (national 8.6%)
A17: 2012 | B17: =Population_by_Year!D26 -> 12493014 | C17: =$C$16+($C$30-$C$16)/(2025-2011)*(2012-2011) -> 0.087785714 | D17: =B17*C17 -> 1096708.1 | E17: Interpolated/Extrapolated | F17: Modeled
A18: 2013 | B18: =Population_by_Year!D27 -> 12544443 | C18: =$C$16+($C$30-$C$16)/(2025-2011)*(2013-2011) -> 0.089571429 | D18: =B18*C18 -> 1123623.7 | E18: Interpolated/Extrapolated | F18: Modeled
A19: 2014 | B19: =Population_by_Year!D28 -> 12596665 | C19: =$C$16+($C$30-$C$16)/(2025-2011)*(2014-2011) -> 0.091357143 | D19: =B19*C19 -> 1150795.3 | E19: Interpolated/Extrapolated | F19: Modeled
A20: 2015 | B20: =Population_by_Year!D29 -> 12649682 | C20: =$C$16+($C$30-$C$16)/(2025-2011)*(2015-2011) -> 0.093142857 | D20: =B20*C20 -> 1178227.5 | E20: Interpolated/Extrapolated | F20: Modeled
A21: 2016 | B21: =Population_by_Year!D30 -> 12703498 | C21: =$C$16+($C$30-$C$16)/(2025-2011)*(2016-2011) -> 0.094928571 | D21: =B21*C21 -> 1205924.9 | E21: Interpolated/Extrapolated | F21: Modeled
A22: 2017 | B22: =Population_by_Year!D31 -> 12758116 | C22: =$C$16+($C$30-$C$16)/(2025-2011)*(2017-2011) -> 0.096714286 | D22: =B22*C22 -> 1233892 | E22: Interpolated/Extrapolated | F22: Modeled
A23: 2018 | B23: =Population_by_Year!D32 -> 12813539 | C23: =$C$16+($C$30-$C$16)/(2025-2011)*(2018-2011) -> 0.0985 | D23: =B23*C23 -> 1262133.6 | E23: Interpolated/Extrapolated | F23: Modeled
A24: 2019 | B24: =Population_by_Year!D33 -> 12869772 | C24: =$C$16+($C$30-$C$16)/(2025-2011)*(2019-2011) -> 0.10028571 | D24: =B24*C24 -> 1290654.3 | E24: Interpolated/Extrapolated | F24: Modeled
A25: 2020 | B25: =Population_by_Year!D34 -> 12926818 | C25: =$C$16+($C$30-$C$16)/(2025-2011)*(2020-2011) -> 0.10207143 | D25: =B25*C25 -> 1319458.8 | E25: Interpolated/Extrapolated | F25: Modeled
A26: 2021 | B26: =Population_by_Year!D35 -> 12984681 | C26: =$C$16+($C$30-$C$16)/(2025-2011)*(2021-2011) -> 0.10385714 | D26: =B26*C26 -> 1348551.8 | E26: Interpolated/Extrapolated | F26: Modeled
A27: 2022 | B27: =Population_by_Year!D36 -> 13043363 | C27: =$C$16+($C$30-$C$16)/(2025-2011)*(2022-2011) -> 0.10564286 | D27: =B27*C27 -> 1377938.2 | E27: Interpolated/Extrapolated | F27: Modeled
A28: 2023 | B28: =Population_by_Year!D37 -> 13102870 | C28: =$C$16+($C$30-$C$16)/(2025-2011)*(2023-2011) -> 0.10742857 | D28: =B28*C28 -> 1407622.6 | E28: Interpolated/Extrapolated | F28: Modeled
A29: 2024 | B29: =Population_by_Year!D38 -> 13163205 | C29: =$C$16+($C$30-$C$16)/(2025-2011)*(2024-2011) -> 0.10921429 | D29: =B29*C29 -> 1437610 | E29: Interpolated/Extrapolated | F29: Modeled
A30: 2025 | B30: =Population_by_Year!D39 -> 13224371 | C30: 0.111 | D30: =B30*C30 -> 1467905.2 | E30: Published estimate (UNDESA) | F30: UNDESA 2008 projection
A31: 2026 | B31: =Population_by_Year!D40 -> 13286373 | C31: =$C$16+($C$30-$C$16)/(2025-2011)*(2026-2011) -> 0.11278571 | D31: =B31*C31 -> 1498513 | E31: Interpolated/Extrapolated | F31: Modeled
A32: 2027 | B32: =Population_by_Year!D41 -> 13349214 | C32: =$C$16+($C$30-$C$16)/(2025-2011)*(2027-2011) -> 0.11457143 | D32: =B32*C32 -> 1529438.5 | E32: Interpolated/Extrapolated | F32: Modeled
A33: 2028 | B33: =Population_by_Year!D42 -> 13412899 | C33: =$C$16+($C$30-$C$16)/(2025-2011)*(2028-2011) -> 0.11635714 | D33: =B33*C33 -> 1560686.6 | E33: Interpolated/Extrapolated | F33: Modeled
A34: 2029 | B34: =Population_by_Year!D43 -> 13477432 | C34: =$C$16+($C$30-$C$16)/(2025-2011)*(2029-2011) -> 0.11814286 | D34: =B34*C34 -> 1592262.3 | E34: Interpolated/Extrapolated | F34: Modeled
A35: 2030 | B35: =Population_by_Year!D44 -> 13542816 | C35: =$C$16+($C$30-$C$16)/(2025-2011)*(2030-2011) -> 0.11992857 | D35: =B35*C35 -> 1624170.6 | E35: Interpolated/Extrapolated | F35: Modeled
A36: 2031 | B36: =Population_by_Year!D45 -> 13609056 | C36: =$C$16+($C$30-$C$16)/(2025-2011)*(2031-2011) -> 0.12171429 | D36: =B36*C36 -> 1656416.6 | E36: Interpolated/Extrapolated | F36: Modeled
